import requests
import logging

def f_911(repo_url: str) -> dict:
    """
    Fetches and returns information about a GitHub repository using its API URL. The function makes an HTTP GET
    request to the provided repository URL. It incorporates error handling for various scenarios including API
    rate limits, other HTTP errors, and general request issues. The function also checks for a large number of
    open issues in the repository and prints a warning if they exceed a certain threshold.

    Parameters:
    - repo_url (str): The URL of the GitHub repository API.

    Returns:
    - dict: A dictionary containing information about the GitHub repository.

    Raises:
    - requests.exceptions.HTTPError: If an HTTP error occurs, particularly when the GitHub API rate limit is
            exceeded.
    - requests.exceptions.RequestException: For other general issues encountered during the API request, such
            as network problems, invalid responses, or timeouts.

    Requirements:
    - requests
    - logging

    Example:
    >>> f_911('https://api.github.com/repos/psf/requests')
    { ... }  # dictionary containing repo information
    >>> f_911('https://api.github.com/repos/some/repo')
    { ... }  # dictionary containing repo information with a possible runtime warning about open issues
    """
    try:
        response = requests.get(repo_url, timeout=2)
        response.raise_for_status()  # Raises HTTPError for bad requests
        repo_info = response.json()
        if (
            response.status_code == 403
            and repo_info.get("message") == "API rate limit exceeded"
        ):
            raise requests.exceptions.HTTPError("API rate limit exceeded")

        if repo_info.get("open_issues_count", 0) > 10000:
            logging.warning("The repository has more than 10000 open issues.")

        return repo_info

    except requests.exceptions.RequestException as e:
        raise requests.exceptions.RequestException(
            f"Error fetching repo info: {e}"
        ) from e


import unittest
from unittest.mock import patch, MagicMock
from io import StringIO
from contextlib import redirect_stdout


class TestCases(unittest.TestCase):
    """Test cases for f_911."""

    @patch("requests.get")
    def test_successful_response(self, mock_get):
        """
        Test f_911 with a successful response.
        """
        mock_get.return_value = MagicMock(
            status_code=200, json=lambda: {"open_issues_count": 5000}
        )
        response = f_911("https://api.github.com/repos/psf/requests")
        self.assertIn("open_issues_count", response)
        self.assertEqual(response["open_issues_count"], 5000)

    @patch("requests.get")
    @patch('logging.warning')
    def test_response_with_more_than_10000_issues(self, mock_warning, mock_get):
        """
        Test f_911 with a response indicating more than 10000 open issues.
        """
        mock_get.return_value = MagicMock(
            status_code=200, json=lambda: {"open_issues_count": 15000}
        )
        
        response = f_911("https://api.github.com/repos/psf/requests")
        
        mock_warning.assert_called_once_with("The repository has more than 10000 open issues.")
        self.assertEqual(response["open_issues_count"], 15000)

    @patch("requests.get")
    def test_api_rate_limit_exceeded(self, mock_get):
        """
        Test f_911 handling API rate limit exceeded error.
        """
        mock_get.return_value = MagicMock(
            status_code=403, json=lambda: {"message": "API rate limit exceeded"}
        )
        with self.assertRaises(Exception) as context:
            f_911("https://api.github.com/repos/psf/requests")
        self.assertIn("API rate limit exceeded", str(context.exception))

    @patch("requests.get")
    def test_http_error(self, mock_get):
        """
        Test f_911 handling HTTP errors.
        """
        mock_get.side_effect = requests.exceptions.HTTPError(
            "404 Client Error: Not Found for url"
        )
        with self.assertRaises(Exception) as context:
            f_911("https://api.github.com/repos/psf/requests")
        self.assertIn("404 Client Error", str(context.exception))

    @patch("requests.get")
    def test_invalid_url(self, mock_get):
        """
        Test f_911 with an invalid URL.
        """
        mock_get.side_effect = requests.exceptions.InvalidURL("Invalid URL")
        with self.assertRaises(Exception) as context:
            f_911("invalid_url")
        self.assertIn("Invalid URL", str(context.exception))


# Running the test cases
def run_tests():
    """Run all tests for this function."""
    loader = unittest.TestLoader()
    suite = loader.loadTestsFromTestCase(TestCases)
    runner = unittest.TextTestRunner()
    runner.run(suite)


if __name__ == "__main__":
    run_tests()
